Workbook

Sheet Roadmap
A1: ID | B1: Task | C1: Module | D1: Priority | E1: Status | F1: Source | G1: Notes | H1: Map Layer | I1: Map Block
A2: CAL-0 | B2: the two shipped defects, before any new feature: add tenantId (+ date range) to GET /api/calendar/events; partition calendar-storage-v1 by tenant and reset on logout/switch/impersonation. Verify: tenant A's events never appear for B; switching tenants clears selections and cached events. | C2: Calendar | D2: P0 | E2: Open | F2: coral-calendar.md:64 | H2: L2 | I2: Calendar module
A3: CAL-1 | B3: the blocker. Mirror api/email/connect/google/route.ts: a dedicated OAuth consent route requesting auth/calendar scope (incremental auth, access_type=offline, prompt=consent for a refresh token), a callback storing tokens bound to (userId, tenantId), and a Connect Google Calendar button + connecte... | C3: Calendar | D3: P0 | E3: Open | F3: coral-calendar.md:65 | H3: L2 | I3: Calendar module
A4: ATT-1 | B4: add to StorageProvider / BlobStorageProvider: | C4: Email attachments | D4: P0 | E4: Done | F4: coral-email-attachments-bug.md:39 | H4: L1 | I4: document engine — attachments
A5: ATT-2 | B5: send-invoice.ts and send-quote.ts. Keep the t_${tenantId}/ tenant check (it's correct and necessary). | C5: Email attachments | D5: P0 | E5: Done | F5: coral-email-attachments-bug.md:52 | H5: L1 | I5: document engine — attachments
A6: ATT-3 | B6: if any selected attachment cannot be fetched: | C6: Email attachments | D6: P0 | E6: Done | F6: coral-email-attachments-bug.md:54 | H6: L1 | I6: document engine — attachments
A7: N1-GRID-CELL-RACE | B7: Sales grid: typing a name then clicking the date cell loses the typed text — whole-row read-modify-write race between cell editors | C7: Engine · Grid | D7: P0 | E7: Open | F7: no spec yet | G7: Needs spec | H7: L3 | I7: grid — write race
A8: PROT-5 | B8: open the existing send modal prefilled (to = supplier email, subject, body, attachment). Do not build a second mail composer. Recipient resolution: supplier's invoice/contact email; if missing, open with an empty To and flag it. CC Florin (the sending tenant owner) by default — his own copy is an... | C8: Finance · Invoice protest | D8: P0 | E8: Open | F8: coral-invoice-protest.md:30 | H8: L3 | I8: Finance — invoice protest
A9: PI-LINES-1 | B9: create getInvoiceLines(page) and use it in every surface (engine view, engine edit, PageModal, PDF template, totals calculation). Resolution order: blocks[financial-row] → properties.invoiceLines (parse the JSON string, tolerate already-parsed arrays) → peppolDetail.lines → []. No component parse... | C9: Finance · Purchase invoices | D9: P0 | E9: Open | F9: coral-purchase-invoice-lines.md:19 | H9: L3 | I9: Finance — purchase invoices
A10: PI-LINES-2 | B10: at import (Peppol inbox + scan), write the lines as financial-row blocks in addition to keeping invoiceLines for provenance. New invoices then render immediately with no edit-and-save ritual. Keep invoiceLines as the raw as-received record — useful for audit and for re-deriving if a mapping bug i... | C10: Finance · Purchase invoices | D10: P0 | E10: Open | F10: coral-purchase-invoice-lines.md:20 | H10: L3 | I10: Finance — purchase invoices
A11: TS-1 | B11: one tenant-scoped aggregation endpoint powering every view/export. Filters: period (from/to, presets: this week / last week / month / custom), worker(s), project(s), team, approval status, entry source (clocked / manual / adjusted). Returns per-entry rows and rollups: hours per worker, per projec... | C11: HR · Timesheet reporting | D11: P0 | E11: Done | F11: coral-timesheet-reporting.md:30 | G11: afbf405 | H11: L3 | I11: HR — timesheets
A12: TS-2b | B12: approval actions exist but are write-only: there is no surface showing what is pending, what was approved/denied, by whom, or when. That makes the approval step unverifiable — and unverifiable approvals are worthless for payroll or a dispute. Implement all of the below as filter/grouping states o... | C12: HR · Timesheet reporting | D12: P0 | E12: Open | F12: coral-timesheet-reporting.md:48 | H12: L3 | I12: HR — timesheets
A13: TS-3 | B13: make the project attribution reliable: | C13: HR · Timesheet reporting | D13: P0 | E13: Open | F13: coral-timesheet-reporting.md:54 | H13: L3 | I13: HR — timesheets
A14: TS-8 | B14: (Florin decision, 2026-07-26) | C14: HR · Timesheet reporting | D14: P0 | E14: Open | F14: coral-timesheet-reporting.md:69 | H14: L3 | I14: HR — timesheets
A15: TSP-1 | B15: replace hrList('clock-entries') with GET /api/hr/timesheet-reports, passing the filter state as query params. Keep the existing approve/deny path (hrUpdate). Default period = this week — never fetch all history by default (today it does). Render summary into StatCards and entries into the existin... | C15: HR · Timesheets page | D15: P0 | E15: In progress | F15: coral-timesheets-page.md:64 | H15: L3 | I15: HR — timesheets page
A16: TSP-5 | B16: inline approve/deny + multi-select bulk with confirmation; reason-for-approval flags visible per row (late · manual · off-geofence · missing clock-out) — a queue without why is just a list; approver + timestamp columns in the approved/denied views; approvals reversible with a trail. Approved and ... | C16: HR · Timesheets page | D16: P0 | E16: Open | F16: coral-timesheets-page.md:68 | H16: L3 | I16: HR — timesheets page
A17: TSP-B1 | B17: (this is why the table looks empty / shows only a few rows). timesheet-reports/route.ts:36,60 applies where.userId = { in: getAccessibleUserIds(...) } unconditionally, and getAccessibleUserIds returns only the caller's own id unless they lead an HrTeam. So a TENANT_OWNER is scoped like a workforc... | C17: HR · Timesheets page | D17: P0 | E17: Done | F17: coral-timesheets-page.md:57 | H17: L3 | I17: HR — timesheets page
A18: TSP-B2 | B18: the page calls useTranslations('Hr.timesheets') (page.tsx:40) but the Hr.timesheets. keys don't exist in messages/{en,nl,fr}.json, so next-intl renders the key paths (Hr.timesheets.title, HR.TIMESHEETS.TOTALHOURS). Same class as TASKS-I18N-NAMES. Add the full block in all three languages using th... | C18: HR · Timesheets page | D18: P0 | E18: Done | F18: coral-timesheets-page.md:58 | H18: L3 | I18: HR — timesheets page
A19: MEM-1 | B19: (cheapest real win — do this first) | C19: Performance · Memory | D19: P0 | E19: Done | F19: coral-memory-investigation.md:37 | H19: L1 | I19: read path — pageIndex, hydration
A20: MEM-3a | B20: ADD THE INDEX — getGlobalPageIndex() + pageIndex store slice; purely additive, do first | C20: Performance · Memory | D20: P0 | E20: Open | F20: coral-mem3-lazy-data.md | H20: L1 | I20: read path — pageIndex, hydration
A21: PROJ-1 | B21: verify the crash is gone (ADMIN-QUERYCLIENT-PROVIDER) and finish its tenant guarding (scoped query keys + clear-on-switch). Nothing else matters until the detail opens reliably. | C21: Projects | D21: P0 | E21: In progress | F21: coral-project-module.md:29 | H21: L3 | I21: Projects
A22: N3-IDLE-CRASH | B22: App idle for a long time crashes: TypeError: Load failed (Safari fetch). Leading hypothesis: Neon autosuspend | C22: Reliability | D22: P0 | E22: Open | F22: coral-memory-investigation.md | G22: Evidence-first | H22: L3 | I22: grid
A23: RCPT-L4b-1 | B23: add onComplete(summary) to the modal; the parent refreshes the store and switches to the Inbox / Te verwerken view. Summary shape: { total, ready, needsReview, failed }. | C23: Scan · Receipt bulk | D23: P0 | E23: Done | F23: coral-receipt-bulk.md:77 | H23: L3 | I23: Expenses — receipts
A24: RCPT-L4b-2 | B24: after each job, insert/refresh the created page in the store so the grid updates as documents complete, not on reload. (Server-first create + no client sync is the same gap that made column visibility "not stick" — see pd.md FORCING FUNCTIONS #1.) | C24: Scan · Receipt bulk | D24: P0 | E24: Done | F24: coral-receipt-bulk.md:78 | H24: L3 | I24: Expenses — receipts
A25: A1 | B25: implement the MISSING submitLateEntry server action in src/app/actions/timesheets.ts (Planner-traced: it doesn't exist → TypeError: s is not a function → "Failed to submit late entry"). Create a PENDING ClockEntry from the input LateEntryCard already sends (targetUserId, clockIn/OutTime, location... | C25: Triage / core | D25: P0 | E25: Done | F25: ground-zero-triage.md:716 | H25: L3 | I25: grid
A26: ADMIN-QUERYCLIENT-PROVIDER | B26: ROOT CAUSE (Planner-traced from the live console): useClockEntries (now React Query) + useScheduledShifts are imported by src/components/admin/database/components/ProjectDetailView.tsx (L12-13, added by workforce-scoping commit 9c0b5ff). The admin app (AdminLayout) has NO QueryClientProvider — on... | C26: Triage / core | D26: P0 | E26: Done | F26: ground-zero-triage.md:663 | H26: ⟂ | I26: deployment / ops
A27: DATA-PERSIST-INTEGRITY | B27: make edits durable and un-clobberable. This is the #1 data-safety fix now that Coral holds real work. | C27: Triage / core | D27: P0 | E27: Open | F27: ground-zero-triage.md:645 | H27: ⟂ | I27: data model
A28: HR-NAV-ROUTES-TO-WORKHUB | B28: STILL BROKEN (Florin re-confirmed 2026-07-12: "click HR still routes to timetracker") — NOT YET APPLIED. The sidebar-order/persistence work (commit 5202fca) landed but this href change was skipped. useSidebarStore.ts:67 still reads href: '/admin/hr/time-tracker' → that route is redirect('/workhub... | C28: Triage / core | D28: P0 | E28: Done | F28: ground-zero-triage.md:412 | H28: L3 | I28: HR / Workforce
A29: OCC-1-REBASELINE | B29: one-line fix, do this first, it alone stops the permanent-conflict loop. | C29: Triage / core | D29: P0 | E29: Done | F29: ground-zero-triage.md:83 | H29: L1 | I29: write path — concurrency
A30: OCC-11-BLOCKSVERSION-REPLACES-HASHING | B30: (ESCALATION — only if OCC-9b doesn't hold. Then it supersedes OCC-9 entirely.) | C30: Triage / core | D30: P0 | E30: Done | F30: ground-zero-triage.md:161 | H30: L1 | I30: write path — concurrency
A31: OCC-12-BLOCKSVERSION-LOST-ITS-QUALIFIERS | B31: (Florin: "OCC-11 didn't cut it either" — 2026-07-27) | C31: Triage / core | D31: P0 | E31: Done | F31: ground-zero-triage.md:178 | H31: L1 | I31: write path — concurrency
A32: OCC-15-SYNC-QUEUE-HAS-NO-SINGLE-FLIGHT-LOCK | B32: (Florin, 2026-07-27, after OCC-14 fixed the general case: "I edited a quote, deleted lines, no protest. The sync issue fires when I edit text.") | C32: Triage / core | D32: P0 | E32: Done | F32: ground-zero-triage.md:227 | H32: L1 | I32: write path — concurrency
A33: OCC-2-SYSTEM-WRITE-TAG | B33: mark non-human writes so they're never reported as "someone else." | C33: Triage / core | D33: P0 | E33: Done | F33: ground-zero-triage.md:90 | H33: L1 | I33: write path — concurrency
A34: OCC-6-BLOCKS-GUARD-TOO-BROAD | B34: REGRESSION — reproducible on EVERY new quote (Florin live, 2026-07-26). | C34: Triage / core | D34: P0 | E34: Done | F34: ground-zero-triage.md:113 | H34: L1 | I34: write path — concurrency
... A53: ATT-4 | B53: the success toast lists the attached filenames, and the sent-record/audit entry stores the attachment list. Then "did the client get the plan?" is answerable from the record instead of from memory. | C53: Email attachments | D53: P1 | E53: Open | F53: coral-email-attachments-bug.md:59 | H53: L1 | I53: document engine — attachments
A54: N2-RELATION-LINK-ICON | B54: Link-back icon on relation fields does not route on many surfaces | C54: Engine · Relations | D54: P1 | E54: Open | F54: no spec yet | G54: Not yet investigated | H54: L3 | I54: grid
A55: PROT-1 | B55: a Protest action on the purchase-invoice record detail (and as a row action in the expenses grid). Opens a small dialog: | C55: Finance · Invoice protest | D55: P1 | E55: Open | F55: coral-invoice-protest.md:19 | H55: L3 | I55: Finance — invoice protest
A56: PROT-2 | B56: resolve in this order: supplier record's language property → tenant default → nl. Support NL / FR / EN (add DE only if a supplier needs it). If the supplier has no language set, default to NL and show which language was chosen in the modal, so a wrong pick is visible before sending, not after. Be... | C56: Finance · Invoice protest | D56: P1 | E56: Open | F56: coral-invoice-protest.md:23 | H56: L3 | I56: Finance — invoice protest
A57: PROT-3 | B57: one template per language (NL / FR / EN), in messages/.json (not hardcoded), composed of: salutation → statement of protest with invoice number, invoice date, amount, supplier name → the reason paragraph (from PROT-1) → free-text detail → what is expected (a credit note AND a corrected invoice — ... | C57: Finance · Invoice protest | D57: P1 | E57: Open | F57: coral-invoice-protest.md:24 | H57: L3 | I57: Finance — invoice protest
A58: PROT-4 | B58: attach the original invoice document (the stored purchase-invoice PDF / scan / Peppol-rendered PDF) to the outgoing mail. Serve via the authenticated /api/files/<key> route — never a bare blob key or public URL (same trap as RECEIPT-BONNETJE-LINK). If the record has no stored document, allow send... | C58: Finance · Invoice protest | D58: P1 | E58: Open | F58: coral-invoice-protest.md:29 | H58: L3 | I58: Finance — invoice protest
...

Sheet Florin - my actions
A1: ID | B1: Action | C1: Status | D1: Priority
A2: ATT-5 | B2: Re-send invoices already sent with annexes selected (went out PDF-only) | C2: Done | D2: P0
A3: HR-5 | B3: Extend Neon PITR window + set snapshot schedule | C3: Done | D3: P1
A4: DEPLOY | B4: Push / deploy / migrations — Florin runs all of these | C4: Ongoing | D4: —
A5: ROADMAP | B5: Mark items noticed in use here, e.g. "to-do P4: ..." | C5: Ongoing | D5: —
A6: MEM-3c | B6: Verify the flagged lazy-load on real data for a week before removing the flag | C6: Open | D6: P1
A7: ACCT-DECISIONS | B7: Decide accountant sharing: mechanism, channel, export format, cadence, scope | C7: Open | D7: P2
A8: TENANTS | B8: Decide when to open free tier / onboard first tenants | C8: Open | D8: P2
A9: MAIL-3 | B9: After MAIL-1 ships: send one invoice, report the toast text | C9: Done | D9: P1
A10: BLOB-4 | B10: DECIDED: strict / all-or-nothing. No partial accountant exports. | C10: Done | D10: P0
A11: BLOB-4b | B11: After BLOB-4: list records already stamped accountantExportedAt whose PDF never shipped, and close the gap by hand (bookkeeping) | C11: Open | D11: P1
A12: SYSTEMS-PASS | B12: APPROVE or re-cut the root order in coral-systems-pass.md (key claim: the grid is a leaf of the write path, not a root) | C12: Open | D12: P0
... A24: SMS-0 | B24: Sweego trial: BE delivery + CORAL sender ID to your phone and one crew phone | C24: Open | D24: P2

Sheet Summary
A1: Metric | B1: Count
A2: Total items | B2: =COUNTA(Roadmap!A2:A334)
A3: Open | B3: =COUNTIF(Roadmap!E2:E334,"Open")
A4: In progress | B4: =COUNTIF(Roadmap!E2:E334,"In progress")
A5: Done | B5: =COUNTIF(Roadmap!E2:E334,"Done")
A7: P0 total | B7: =COUNTIF(Roadmap!D2:D334,"P0")
A8: P0 still open | B8: =COUNTIFS(Roadmap!D2:D334,"P0",Roadmap!E2:E334,"Open")
A9: P1 total | B9: =COUNTIF(Roadmap!D2:D334,"P1")
A10: P1 still open | B10: =COUNTIFS(Roadmap!D2:D334,"P1",Roadmap!E2:E334,"Open")
A11: P2 total | B11: =COUNTIF(Roadmap!D2:D334,"P2")
A12: P2 still open | B12: =COUNTIFS(Roadmap!D2:D334,"P2",Roadmap!E2:E334,"Open")
A13: P3 total | B13: =COUNTIF(Roadmap!D2:D334,"P3")
A14: P3 still open | B14: =COUNTIFS(Roadmap!D2:D334,"P3",Roadmap!E2:E334,"Open")
A15: P4 total | B15: =COUNTIF(Roadmap!D2:D334,"P4")
A16: P4 still open | B16: =COUNTIFS(Roadmap!D2:D334,"P4",Roadmap!E2:E334,"Open")
A18: By module — open
A19: Automations | B19: =COUNTIFS(Roadmap!C2:C334,"Automations",Roadmap!E2:E334,"Open")
A20: Calendar | B20: =COUNTIFS(Roadmap!C2:C334,"Calendar",Roadmap!E2:E334,"Open")
A21: Email attachments | B21: =COUNTIFS(Roadmap!C2:C334,"Email attachments",Roadmap!E2:E334,"Open")
A22: Engine · Grid | B22: =COUNTIFS(Roadmap!C2:C334,"Engine · Grid",Roadmap!E2:E334,"Open")
A23: Engine · Relations | B23: =COUNTIFS(Roadmap!C2:C334,"Engine · Relations",Roadmap!E2:E334,"Open")
A24: Finance · Invoice protest | B24: =COUNTIFS(Roadmap!C2:C334,"Finance · Invoice protest",Roadmap!E2:E334,"Open")
A25: Finance · Purchase invoices | B25: =COUNTIFS(Roadmap!C2:C334,"Finance · Purchase invoices",Roadmap!E2:E334,"Open")
A26: Finance · Purchase orders | B26: =COUNTIFS(Roadmap!C2:C334,"Finance · Purchase orders",Roadmap!E2:E334,"Open")
A27: HR · Timesheet reporting | B27: =COUNTIFS(Roadmap!C2:C334,"HR · Timesheet reporting",Roadmap!E2:E334,"Open")
A28: HR · Timesheets page | B28: =COUNTIFS(Roadmap!C2:C334,"HR · Timesheets page",Roadmap!E2:E334,"Open")
A29: Mobile | B29: =COUNTIFS(Roadmap!C2:C334,"Mobile",Roadmap!E2:E334,"Open")
A30: Mobile / PWA | B30: =COUNTIFS(Roadmap!C2:C334,"Mobile / PWA",Roadmap!E2:E334,"Open")
A31: Performance · Memory | B31: =COUNTIFS(Roadmap!C2:C334,"Performance · Memory",Roadmap!E2:E334,"Open")
A32: Pro Hardening | B32: =COUNTIFS(Roadmap!C2:C334,"Pro Hardening",Roadmap!E2:E334,"Open")
A33: Projects | B33: =COUNTIFS(Roadmap!C2:C334,"Projects",Roadmap!E2:E334,"Open")
A34: Reliability | B34: =COUNTIFS(Roadmap!C2:C334,"Reliability",Roadmap!E2:E334,"Open")
A35: Scan · Receipt bulk | B35: =COUNTIFS(Roadmap!C2:C334,"Scan · Receipt bulk",Roadmap!E2:E334,"Open")
A36: Triage / core | B36: =COUNTIFS(Roadmap!C2:C334,"Triage / core",Roadmap!E2:E334,"Open")
A38: BY MAP LAYER
A39: L0 | B39: 21
A40: L1 | B40: 84
A41: GATE | B41: 12
A42: L2 | B42: 20
A43: MODULE GATE | B43: 2
...
